Workbook

Sheet Du Pont
A1: CUADRO DE MANDO DE DU PONT
D3: Ventas
D4: =+ER!D10 -> 0
D8: Costo de Ventas
D9: =+ER!D11 -> 0
H10: Utilidad d. Impuestos
H11: =D4-D9-D14-D19-D24 -> #REF!
A12: Estado de Resultados
A13: o | D13: Gastos Operativos | L13: Margen Neto
A14: Estado de Ganancias | D14: =+ER!#REF!*-1 -> #REF! | L14: =IFERROR(H11/H17,0) -> 0
A15: y Pérdidas
H16: Ventas
H17: =D4 -> 0
D18: Gastos por Intereses
D19: =+ER!D27*-1 -> 0
D23: Impuestos | P23: Rendimto. Act. Tot.
D24: 0 | P24: =L14*L34 -> 0
H30: Ventas
H31: =D4 -> 0
L33: Rotación de Activos
D34: Activo Corriente | L34: =IFERROR(H31/H37,0) -> 0
D35: =+BG!D21 -> 0
H36: Activos Totales
H37: =D35+D40 -> 0
T38: Rendimto. Capital
D39: Activo Fijo Neto | T39: =P24*P54 -> 0
D40: =+BG!D23 -> 0
A43: Estado de Situación
A44: Financiera o | D44: Pasivo a Corto Plazo
A45: Balance General | D45: =+BG!D42 -> 0
H47: Pasivos Totales
H48: =D45+D50 -> 0
D49: Pasivo a Largo Plazo
D50: =+BG!D51 -> 0 | L50: T. Pvo. y Cap. = Act. T.
L51: =H48+H54 -> 0
H53: Capital Contable | P53: Multip. Apalan. Finan.
H54: =+BG!D62 -> 0 | P54: =IFERROR(L51/L57,0) -> 0
L56: Capital Contable
L57: =H54 -> 0

Sheet Analiticas
C2: 2021 | D2: 2022 | E2: 2023 | G2: Observaciones
A4: Clientes
A7: Leonardo Services SA de CV
A8: NUCITEC SA DE CV
A9: Luis Fernando Maya Suarez
A10: Servicios Terrestres Empresariales
A11: POS CLOUDS DE MEXICO SA DE CV
A12: ELICAMEX
A13: AUTOCOM NOVA SAPI SA DE CV
A14: MEXARREND SAPI DE CV
A15: ASCENTY MEXICO S DE RL DE CV
A16: GERARDO CHAPARRO ARIAS
A21: Total | C21: =SUM(C7:C20) -> 0 | D21: =SUM(D7:D20) -> 0 | E21: =SUM(E7:E20) -> 0
A23: Anticipo a Proveedores
A25: AUTOCOM NOVA SAPI DE CV
A26: VAQSA
A27: SERVICIOS GASOLINEROS DE MEXICO SA DE CV
A28: GASOLINERIA NUEVO MILENIO SA DE CV
A29: ALMA ROSA CHAPARRO ARIAS
A30: VOLKSWAGEN LEASING
A31: GM FINANCIAL DE MEXICO SA DE CV SOFOM ENR
A32: TELMOV SA DE CV
A33: MYLSA QRO
A34: RADIOMOVIL DIPSA
A35: FINANCIERA BEPENSA
... A48: COMERCIALIZADORA DE VEHICULOS Y REFACCIONES DE OCC
A52: Total | C52: =SUM(C25:C50) -> 0 | D52: =SUM(D25:D50) -> 0 | E52: =SUM(E25:E50) -> 0
A54: Deudores Diversos
A59: Total | C59: =SUM(C56:C58) -> 0 | D59: =SUM(D56:D58) -> 0 | E59: =SUM(E56:E58) -> 0
A63: Financiamiento
A65: Acreedores
A67: ALMA ROSA CHAPARRO ARIAS
A68: CIGUEÑALES Y RECTIFICACIONES VAZQUEZ
A69: DAVID BARRIOS
A70: JOSE JESUS MERCADILLO ESCOBEDO
A71: LEONARDO SERVICES SA DE CV
A72: MAXIMA HOTELERA
A73: NOE TORRES DOMINGUEZ
A74: SERVICIOS TERRESTRES EMPRESARIALES
A75: VAQCSA VENTO 2
...

Sheet BG
A5: Prospecto: TA SOLUCIONES
A6: Estado de Situacion Financiera
A8: CONCEPTO | B8: 2021 | C8: 2022 | D8: 2023 | E8: 2024 | F8: 2025 | G8: 46023 | I8: % 23-24 | J8: %24-25 | K8: %25-26
A9: Activo
A10: Activo circulante:
A11: Efectivo, equivalentes de efectivo y efectivo restringido | I11: =+E11/D11-1 -> #DIV/0! | J11: =+F11/E11-1 -> #DIV/0! | K11: =+G11/F11-1 -> #DIV/0!
A12: Clientes | I12: =+E12/D12-1 -> #DIV/0! | J12: =+F12/E12-1 -> #DIV/0! | K12: =+G12/F12-1 -> #DIV/0!
A13: Inventario | I13: =+E13/D13-1 -> #DIV/0! | J13: =+F13/E13-1 -> #DIV/0! | K13: =+G13/F13-1 -> #DIV/0!
A14: Proyectos en proceso | I14: =+E14/D14-1 -> #DIV/0! | J14: =+F14/E14-1 -> #DIV/0! | K14: =+G14/F14-1 -> #DIV/0!
A15: Partes relacionadas | I15: =+E15/D15-1 -> #DIV/0! | J15: =+F15/E15-1 -> #DIV/0! | K15: =+G15/F15-1 -> #DIV/0!
A16: Impuestos al valor agregado | I16: =+E16/D16-1 -> #DIV/0! | J16: =+F16/E16-1 -> #DIV/0! | K16: =+G16/F16-1 -> #DIV/0!
A17: Pagos anticipados | I17: =+E17/D17-1 -> #DIV/0! | J17: =+F17/E17-1 -> #DIV/0! | K17: =+G17/F17-1 -> #DIV/0!
A18: Impuestos por acreditar | I18: =+E18/D18-1 -> #DIV/0! | J18: =+F18/E18-1 -> #DIV/0! | K18: =+G18/F18-1 -> #DIV/0!
A19: Otras cuentas por cobrar | I19: =+E19/D19-1 -> #DIV/0! | J19: =+F19/E19-1 -> #DIV/0! | K19: =+G19/F19-1 -> #DIV/0!
A21: Total del activo circulante | B21: =SUM(B11:B20) -> 0 | C21: =SUM(C11:C20) -> 0 | D21: =SUM(D11:D20) -> 0 | E21: =SUM(E11:E20) -> 0 | F21: =SUM(F11:F20) -> 0 | G21: =SUM(G11:G20) -> 0 | I21: =+E21/D21-1 -> #DIV/0! | J21: =+F21/E21-1 -> #DIV/0! | K21: =+G21/F21-1 -> #DIV/0!
A23: Equipo de Oficina y Equipo de Transporte (neto) | I23: =+E23/D23-1 -> #DIV/0! | J23: =+F23/E23-1 -> #DIV/0! | K23: =+G23/F23-1 -> #DIV/0!
A25: Activo Diferido | B25: =SUM(B26:B28) -> 0 | I25: =+E25/D25-1 -> #DIV/0! | J25: =+F25/E25-1 -> #DIV/0! | K25: =+G25/F25-1 -> #DIV/0!
A26: Deposito en Garantia | I26: =+E26/D26-1 -> #DIV/0! | J26: =+F26/E26-1 -> #DIV/0! | K26: =+G26/F26-1 -> #DIV/0!
A27: Mejoras y Gastos de instalacion | I27: =+E27/D27-1 -> #DIV/0! | J27: =+F27/E27-1 -> #DIV/0! | K27: =+G27/F27-1 -> #DIV/0!
A28: Impuestos a Favor | I28: =+E28/D28-1 -> #DIV/0! | J28: =+F28/E28-1 -> #DIV/0! | K28: =+G28/F28-1 -> #DIV/0!
A29: Pagos Anticipados | I29: =+E29/D29-1 -> #DIV/0! | J29: =+F29/E29-1 -> #DIV/0! | K29: =+G29/F29-1 -> #DIV/0!
A30: Total Activo Diferido | C30: =SUM(C26:C29) -> 0 | D30: =SUM(D26:D29) -> 0 | E30: =SUM(E26:E29) -> 0 | F30: =SUM(F26:F29) -> 0 | G30: =SUM(G26:G29) -> 0 | I30: =+E30/D30-1 -> #DIV/0! | J30: =+F30/E30-1 -> #DIV/0! | K30: =+G30/F30-1 -> #DIV/0!
A31: Total del activo | B31: =+B21+B23+B25 -> 0 | C31: =+C21+C23+C30 -> 0 | D31: =+D21+D23+D30 -> 0 | E31: =+E21+E23+E30 -> 0 | F31: =+F21+F23+F30 -> 0 | G31: =+G21+G23+G30 -> 0 | I31: =+E31/D31-1 -> #DIV/0! | J31: =+F31/E31-1 -> #DIV/0! | K31: =+G31/F31-1 -> #DIV/0!
A34: Préstamos de instituciones financieras
A35: Proveedores | I35: =+E35/D35-1 -> #DIV/0! | J35: =+F35/E35-1 -> #DIV/0! | K35: =+G35/F35-1 -> #DIV/0!
A36: Acreedores Diversos | I36: =+E36/D36-1 -> #DIV/0! | J36: =+F36/E36-1 -> #DIV/0! | K36: =+G36/F36-1 -> #DIV/0!
A37: Anticipo de Clientes | I37: =+E37/D37-1 -> #DIV/0! | J37: =+F37/E37-1 -> #DIV/0! | K37: =+G37/F37-1 -> #DIV/0!
A38: Iva Trasladado | I38: =+E38/D38-1 -> #DIV/0! | J38: =+F38/E38-1 -> #DIV/0! | K38: =+G38/F38-1 -> #DIV/0!
A39: Impuestos por pagar | I39: =+E39/D39-1 -> #DIV/0! | J39: =+F39/E39-1 -> #DIV/0! | K39: =+G39/F39-1 -> #DIV/0!
A40: PTU por Pagar | I40: =+E40/D40-1 -> #DIV/0! | J40: =+F40/E40-1 -> #DIV/0! | K40: =+G40/F40-1 -> #DIV/0!
A41: Otros pasivos a corto plazo | I41: =+E41/D41-1 -> #DIV/0! | J41: =+F41/E41-1 -> #DIV/0! | K41: =+G41/F41-1 -> #DIV/0!
A42: Total del pasivo circulante | B42: =SUM(B34:B41) -> 0 | C42: =SUM(C34:C41) -> 0 | D42: =SUM(D34:D41) -> 0 | E42: =SUM(E34:E41) -> 0 | F42: =SUM(F34:F41) -> 0 | G42: =SUM(G34:G41) -> 0 | I42: =+E42/D42-1 -> #DIV/0! | J42: =+F42/E42-1 -> #DIV/0! | K42: =+G42/F42-1 -> #DIV/0!
A44: Préstamos de instituciones financieras | I44: =+E44/D44-1 -> #DIV/0! | J44: =+F44/E44-1 -> #DIV/0! | K44: =+G44/F44-1 -> #DIV/0!
A46: Total del pasivo largo Plazo | B46: =SUM(B43:B44) -> 0 | C46: =SUM(C43:C44) -> 0 | D46: =SUM(D43:D44) -> 0 | E46: =SUM(E43:E44) -> 0 | F46: =SUM(F43:F44) -> 0 | G46: =SUM(G43:G44) -> 0 | I46: =+E46/D46-1 -> #DIV/0! | J46: =+F46/E46-1 -> #DIV/0! | K46: =+G46/F46-1 -> #DIV/0!
A52: Total otros pasivos | B52: =SUM(B48:B50) -> 0 | C52: =SUM(C48:C50) -> 0 | D52: =SUM(D48:D50) -> 0 | E52: =SUM(E48:E50) -> 0 | F52: =SUM(F48:F50) -> 0 | G52: =SUM(G48:G50) -> 0 | I52: =+E52/D52-1 -> #DIV/0! | J52: =+F52/E52-1 -> #DIV/0! | K52: =+G52/F52-1 -> #DIV/0!
A54: Total del pasivo | B54: =+B42+B46+B52 -> 0 | C54: =+C42+C46+C52 -> 0 | D54: =+D42+D46+D52 -> 0 | E54: =+E42+E46+E52 -> 0 | F54: =+F42+F46+F52 -> 0 | G54: =+G42+G46+G52 -> 0 | I54: =+E54/D54-1 -> #DIV/0! | J54: =+F54/E54-1 -> #DIV/0! | K54: =+G54/F54-1 -> #DIV/0!
A55: Capital contable:
A56: Capital social | I56: =+E56/D56-1 -> #DIV/0! | J56: =+F56/E56-1 -> #DIV/0! | K56: =+G56/F56-1 -> #DIV/0!
A57: Aportaciones para futuros aumento a Capital | I57: =+E57/D57-1 -> #DIV/0! | J57: =+F57/E57-1 -> #DIV/0! | K57: =+G57/F57-1 -> #DIV/0!
A58: Reserva Legal | I58: =+E58/D58-1 -> #DIV/0! | J58: =+F58/E58-1 -> #DIV/0! | K58: =+G58/F58-1 -> #DIV/0!
...

Sheet ER
A5: Prospecto: TA SOLUCIONES
A6: Estado de Resultados
A8: CONCEPTO | B8: 2021 | C8: 2022 | D8: 2023 | E8: 2024 | F8: 2025 | G8: 46023 | I8: % 23-24 | J8: %24-25 | K8: %25-26
A10: Ingresos | I10: =+E10/D10-1 -> #DIV/0! | J10: =+F10/E10-1 -> #DIV/0! | K10: =+G10/F10-1 -> #DIV/0!
A12: Costo de Ventas | C12: 0 | D12: 0 | E12: 0 | F12: 0 | G12: 0 | I12: =+E12/D12-1 -> #DIV/0! | J12: =+F12/E12-1 -> #DIV/0! | K12: =+G12/F12-1 -> #DIV/0!
A14: Utilidad Bruta | B14: =+B10-B12 -> 0 | C14: =+C10-C12 -> 0 | D14: =+D10-D12 -> 0 | E14: =+E10-E12 -> 0 | F14: =+F10-F12 -> 0 | G14: =+G10-G12 -> 0 | I14: =+E14/D14-1 -> #DIV/0! | J14: =+F14/E14-1 -> #DIV/0! | K14: =+G14/F14-1 -> #DIV/0!
A16: Gastos de operación | B16: =SUM(B18:B19) -> 0 | C16: =SUM(C18:C19) -> 0 | D16: =SUM(D18:D19) -> 0 | E16: =SUM(E18:E19) -> 0 | F16: =SUM(F18:F19) -> 0 | G16: =SUM(G18:G19) -> 0 | I16: =+E16/D16-1 -> #DIV/0! | J16: =+F16/E16-1 -> #DIV/0! | K16: =+G16/F16-1 -> #DIV/0!
A18: Gastos de Operación | I18: =+E18/D18-1 -> #DIV/0! | J18: =+F18/E18-1 -> #DIV/0! | K18: =+G18/F18-1 -> #DIV/0!
A21: Utilidad antes de Productos Financieros | B21: =+B14-B16 -> 0 | C21: =+C14-C16 -> 0 | D21: =+D14-D16 -> 0 | E21: =+E14-E16 -> 0 | F21: =+F14-F16 -> 0 | G21: =+G14-G16 -> 0 | I21: =+E21/D21-1 -> #DIV/0! | J21: =+F21/E21-1 -> #DIV/0! | K21: =+G21/F21-1 -> #DIV/0!
A23: Intereses a favor
A24: Intereses a cargo | I24: =+E24/D24-1 -> #DIV/0! | J24: =+F24/E24-1 -> #DIV/0! | K24: =+G24/F24-1 -> #DIV/0!
A25: Utilidad cambiaria | I25: =+E25/D25-1 -> #DIV/0! | J25: =+F25/E25-1 -> #DIV/0! | K25: =+G25/F25-1 -> #DIV/0!
A26: Perdida cambiaria | I26: =+E26/D26-1 -> #DIV/0! | J26: =+F26/E26-1 -> #DIV/0! | K26: =+G26/F26-1 -> #DIV/0!
A28: Utilidad antes de otros ingresos/gastos | B28: =+B21+B23-B24+B25-B26 -> 0 | C28: =+C21+C23-C24+C25-C26 -> 0 | D28: =+D21+D23-D24+D25-D26 -> 0 | E28: =+E21+E23-E24+E25-E26 -> 0 | F28: =+F21+F23-F24+F25-F26 -> 0 | G28: =+G21+G23-G24+G25-G26 -> 0 | I28: =+E28/D28-1 -> #DIV/0! | J28: =+F28/E28-1 -> #DIV/0! | K28: =+G28/F28-1 -> #DIV/0!
A30: Otros ingresos (otros gastos) | I30: =+E30/D30-1 -> #DIV/0! | J30: =+F30/E30-1 -> #DIV/0! | K30: =+G30/F30-1 -> #DIV/0!
A32: Utilidad antes de impuestos | B32: =+B28-B30 -> 0 | C32: =+C28-C30 -> 0 | D32: =+D28-D30 -> 0 | E32: =+E28-E30 -> 0 | F32: =+F28-F30 -> 0 | G32: =+G28-G30 -> 0 | I32: =+E32/D32-1 -> #DIV/0! | J32: =+F32/E32-1 -> #DIV/0! | K32: =+G32/F32-1 -> #DIV/0!
A33: (-) ISR | I33: =+E33/D33-1 -> #DIV/0! | J33: =+F33/E33-1 -> #DIV/0! | K33: =+G33/F33-1 -> #DIV/0!
A34: (-) PTU por Pagar | I34: =+E34/D34-1 -> #DIV/0! | J34: =+F34/E34-1 -> #DIV/0! | K34: =+G34/F34-1 -> #DIV/0!
A35: Utilidad neta | B35: =+B32-B33-B34 -> 0 | C35: =+C32-C33-C34 -> 0 | D35: =+D32-D33-D34 -> 0 | E35: =+E32-E33-E34 -> 0 | F35: =+F32-F33-F34 -> 0 | G35: =+G32-G33-G34 -> 0 | I35: =+E35/D35-1 -> #DIV/0! | J35: =+F35/E35-1 -> #DIV/0! | K35: =+G35/F35-1 -> #DIV/0!

Sheet RF
A5: Prospecto: TA SOLUCIONES
A6: Razones Financieras
A8: CONCEPTO | B8: 2021 | C8: 2022 | D8: 2023 | E8: 2024 | F8: 2025 | G8: 46023 | I8: Var% 21 vs 22 | J8: Var% 22 vs 23 | K8: Var% 23 vs 24 | L8: Var% 24 vs 25 | M8: Var% 25 vs 26
A10: Solvencia y Viabilidad
A12: Activos Totales | B12: =+BG!B31 -> 0 | C12: =+BG!C31 -> 0 | D12: =+BG!D31 -> 0 | E12: =+BG!E31 -> 0 | F12: =+BG!F31 -> 0 | G12: =+BG!G31 -> 0 | I12: =(+C12/B12)-1 -> #DIV/0! | J12: =(+D12/C12)-1 -> #DIV/0! | K12: =(+E12/D12)-1 -> #DIV/0! | L12: =(+F12/E12)-1 -> #DIV/0! | M12: =(+G12/F12)-1 -> #DIV/0!
A13: Deuda total / Activos Totales | B13: =SUM(BG!B43)/RF!B12 -> #DIV/0! | C13: =SUM(BG!C34+BG!C44)/RF!C12 -> #DIV/0! | D13: =SUM(BG!D34+BG!D44)/RF!D12 -> #DIV/0! | E13: =SUM(BG!E34+BG!E44)/RF!E12 -> #DIV/0! | F13: =SUM(BG!F34+BG!F44)/RF!F12 -> #DIV/0! | G13: =SUM(BG!G34+BG!G44)/RF!G12 -> #DIV/0! | I13: =(+C13/B13)-1 -> #DIV/0! | J13: =(+D13/C13)-1 -> #DIV/0! | K13: =(+E13/D13)-1 -> #DIV/0! | L13: =(+F13/E13)-1 -> #DIV/0! | M13: =(+G13/F13)-1 -> #DIV/0!
A14: Apalancamiento | B14: =SUM(BG!B42+BG!B46)/BG!B62 -> #DIV/0! | C14: =SUM(BG!C42+BG!C46+BG!C52)/BG!C62 -> #DIV/0! | D14: =SUM(BG!D42+BG!D46+BG!D52)/BG!D62 -> #DIV/0! | E14: =SUM(BG!E42+BG!E46+BG!E52)/BG!E62 -> #DIV/0! | F14: =SUM(BG!F42+BG!F46+BG!F52)/BG!F62 -> #DIV/0! | G14: =SUM(BG!G42+BG!G46+BG!G52)/BG!G62 -> #DIV/0! | I14: =(+C14/B14)-1 -> #DIV/0! | J14: =(+D14/C14)-1 -> #DIV/0! | K14: =(+E14/D14)-1 -> #DIV/0! | L14: =(+F14/E14)-1 -> #DIV/0! | M14: =(+G14/F14)-1 -> #DIV/0!
A15: Activos Fijos / Activos Totales | B15: =+BG!B23/BG!B31 -> #DIV/0! | C15: =+BG!C23/BG!C31 -> #DIV/0! | D15: =+BG!D23/BG!D31 -> #DIV/0! | E15: =+BG!E23/BG!E31 -> #DIV/0! | F15: =+BG!F23/BG!F31 -> #DIV/0! | G15: =+BG!G23/BG!G31 -> #DIV/0! | I15: =(+C15/B15)-1 -> #DIV/0! | J15: =(+D15/C15)-1 -> #DIV/0! | K15: =(+E15/D15)-1 -> #DIV/0! | L15: =(+F15/E15)-1 -> #DIV/0! | M15: =(+G15/F15)-1 -> #DIV/0!
A17: Ciclo
A19: Rotación de cuentas por cobrar (días) | B19: =SUM(BG!B13/ER!B10)*360 -> #DIV/0! | C19: =SUM(BG!C12/ER!C10)*360 -> #DIV/0! | D19: =SUM(BG!D12/ER!D10)*360 -> #DIV/0! | E19: =SUM(BG!E12/ER!E10)*360 -> #DIV/0! | F19: =SUM(BG!F12/ER!F10)*360 -> #DIV/0! | G19: =SUM(BG!G12/ER!G10)*360 -> #DIV/0! | I19: =(+C19/B19)-1 -> #DIV/0! | J19: =(+D19/C19)-1 -> #DIV/0! | K19: =(+E19/D19)-1 -> #DIV/0! | L19: =(+F19/E19)-1 -> #DIV/0! | M19: =(+G19/F19)-1 -> #DIV/0!
A20: Rotación de inventarios | B20: =(+BG!B15/ER!B12)*360 -> #DIV/0! | C20: =(+BG!C13/ER!C12)*360 -> #DIV/0! | D20: =(+BG!D13/ER!D12)*360 -> #DIV/0! | E20: =(+BG!E13/ER!E12)*360 -> #DIV/0! | F20: =(+BG!F13/ER!F12)*360 -> #DIV/0! | G20: =(+BG!G13/ER!G12)*360 -> #DIV/0! | I20: =(+C20/B20)-1 -> #DIV/0! | J20: =(+D20/C20)-1 -> #DIV/0! | K20: =(+E20/D20)-1 -> #DIV/0! | L20: =(+F20/E20)-1 -> #DIV/0! | M20: =(+G20/F20)-1 -> #DIV/0!
A21: Rotación de Cuentas por Pagar | B21: =SUM(BG!B34/ER!B12)*360 -> #DIV/0! | C21: =SUM(BG!C35/ER!C12)*360 -> #DIV/0! | D21: =SUM(BG!D35/ER!D12)*360 -> #DIV/0! | E21: =SUM(BG!E35/ER!E12)*360 -> #DIV/0! | F21: =SUM(BG!F35/ER!F12)*360 -> #DIV/0! | G21: =SUM(BG!G35/ER!G12)*360 -> #DIV/0! | I21: =(+C21/B21)-1 -> #DIV/0! | J21: =(+D21/C21)-1 -> #DIV/0! | K21: =(+E21/D21)-1 -> #DIV/0! | L21: =(+F21/E21)-1 -> #DIV/0! | M21: =(+G21/F21)-1 -> #DIV/0!
A24: Rentabilidad y Liquidez
A26: Activo Circulante/Pasivo a Corto Plazo | B26: =+BG!B21/BG!B42 -> #DIV/0! | C26: =+BG!C21/BG!C42 -> #DIV/0! | D26: =+BG!D21/BG!D42 -> #DIV/0! | E26: =+BG!E21/BG!E42 -> #DIV/0! | F26: =+BG!F21/BG!F42 -> #DIV/0! | G26: =+BG!G21/BG!G42 -> #DIV/0! | I26: =(+C26/B26)-1 -> #DIV/0! | J26: =(+D26/C26)-1 -> #DIV/0! | K26: =(+E26/D26)-1 -> #DIV/0! | L26: =(+F26/E26)-1 -> #DIV/0! | M26: =(+G26/F26)-1 -> #DIV/0!
A27: Ventas / Activos Totales | B27: =+ER!B10/RF!B12 -> #DIV/0! | C27: =+ER!C10/RF!C12 -> #DIV/0! | D27: =+ER!D10/RF!D12 -> #DIV/0! | E27: =+ER!E10/RF!E12 -> #DIV/0! | F27: =+ER!F10/RF!F12 -> #DIV/0! | G27: =+ER!G10/RF!G12 -> #DIV/0! | I27: =(+C27/B27)-1 -> #DIV/0! | J27: =(+D27/C27)-1 -> #DIV/0! | K27: =(+E27/D27)-1 -> #DIV/0! | L27: =(+F27/E27)-1 -> #DIV/0! | M27: =(+G27/F27)-1 -> #DIV/0!
A28: Ventas Anuales | B28: =+ER!B10 -> 0 | C28: =+ER!C10 -> 0 | D28: =+ER!D10 -> 0 | E28: =+ER!E10 -> 0 | F28: =+ER!F10 -> 0 | G28: =+ER!G10 -> 0 | I28: =(+C28/B28)-1 -> #DIV/0! | J28: =(+D28/C28)-1 -> #DIV/0! | K28: =(+E28/D28)-1 -> #DIV/0! | L28: =(+F28/E28)-1 -> #DIV/0! | M28: =(+G28/F28)-1 -> #DIV/0!
A29: Utilidad del Ejercicio | B29: =+ER!B35 -> 0 | C29: =+ER!C35 -> 0 | D29: =+ER!D35 -> 0 | E29: =+ER!E35 -> 0 | F29: =+ER!F35 -> 0 | G29: =+ER!G35 -> 0 | I29: =(+C29/B29)-1 -> #DIV/0! | J29: =(+D29/C29)-1 -> #DIV/0! | K29: =(+E29/D29)-1 -> #DIV/0! | L29: =(+F29/E29)-1 -> #DIV/0! | M29: =(+G29/F29)-1 -> #DIV/0!
A30: Ciclo Financiero | B30: =+B19+B20-B21 -> #DIV/0! | C30: =+C19+C20-C21 -> #DIV/0! | D30: =+D19+D20-D21 -> #DIV/0! | E30: =+E19+E20-E21 -> #DIV/0! | F30: =+F19+F20-F21 -> #DIV/0! | G30: =+G19+G20-G21 -> #DIV/0! | I30: =(+C30/B30)-1 -> #DIV/0! | J30: =(+D30/C30)-1 -> #DIV/0! | K30: =(+E30/D30)-1 -> #DIV/0! | L30: =(+F30/E30)-1 -> #DIV/0! | M30: =(+G30/F30)-1 -> #DIV/0!
A31: Margen Utilidad | B31: =+B29/B28 -> #DIV/0! | C31: =+C29/C28 -> #DIV/0! | D31: =+D29/D28 -> #DIV/0! | E31: =+E29/E28 -> #DIV/0! | F31: =+F29/F28 -> #DIV/0! | G31: =+G29/G28 -> #DIV/0! | I31: =(+C31/B31)-1 -> #DIV/0! | J31: =(+D31/C31)-1 -> #DIV/0! | K31: =(+E31/D31)-1 -> #DIV/0! | L31: =(+F31/E31)-1 -> #DIV/0! | M31: =(+G31/F31)-1 -> #DIV/0!
A32: Margen UAFIR | B32: =SUM(ER!B21/ER!B10) -> #DIV/0! | C32: =SUM(ER!C21/ER!C10) -> #DIV/0! | D32: =SUM(ER!D21/ER!D10) -> #DIV/0! | E32: =SUM(ER!E21/ER!E10) -> #DIV/0! | F32: =SUM(ER!F21/ER!F10) -> #DIV/0! | G32: =SUM(ER!G21/ER!G10) -> #DIV/0! | I32: =(+C32/B32)-1 -> #DIV/0! | J32: =(+D32/C32)-1 -> #DIV/0! | K32: =(+E32/D32)-1 -> #DIV/0! | L32: =(+F32/E32)-1 -> #DIV/0! | M32: =(+G32/F32)-1 -> #DIV/0!
A33: ROA | B33: =+B29/B12 -> #DIV/0! | C33: =+C29/C12 -> #DIV/0! | D33: =+D29/D12 -> #DIV/0! | E33: =+E29/E12 -> #DIV/0! | F33: =+F29/F12 -> #DIV/0! | G33: =+G29/G12 -> #DIV/0! | I33: =(+C33/B33)-1 -> #DIV/0! | J33: =(+D33/C33)-1 -> #DIV/0! | K33: =(+E33/D33)-1 -> #DIV/0! | L33: =(+F33/E33)-1 -> #DIV/0! | M33: =(+G33/F33)-1 -> #DIV/0!
A34: ROE | B34: =+B29/BG!B62 -> #DIV/0! | C34: =+C29/BG!C62 -> #DIV/0! | D34: =+D29/BG!D62 -> #DIV/0! | E34: =+E29/BG!E62 -> #DIV/0! | F34: =+F29/BG!F62 -> #DIV/0! | G34: =+G29/BG!G62 -> #DIV/0! | I34: =(+C34/B34)-1 -> #DIV/0! | J34: =(+D34/C34)-1 -> #DIV/0! | K34: =(+E34/D34)-1 -> #DIV/0! | L34: =(+F34/E34)-1 -> #DIV/0! | M34: =(+G34/F34)-1 -> #DIV/0!
A37: Margen de utilidad/Prestamo | D37: =+D29/D38 -> #DIV/0! | E37: =+E29/E38 -> #DIV/0! | F37: =+F29/F38 -> #DIV/0! | G37: =+G29/G38 -> #DIV/0!
A38: Prestamo anual | D38: 0 | E38: 0 | F38: 0 | G38: 0
A40: Promedio ultimos 3 años | E40: =AVERAGE(D29:F29) -> 0 | F40: =+E40/E38 -> #DIV/0!
A41: Promedio ultimos 2 años | E41: =AVERAGE(E29:F29) -> 0 | F41: =+E41/E38 -> #DIV/0!

Sheet Modelo de Crédito
B1: Modelo de Crédito: TA SOLUCIONES
B2: Calificacion de Credito
B3: 90-100
B4: 80-90
B5: 70-80
B6: 60-70
B7: 50-60
B9: Historial Crediticio y de Administración 40%
A10: Peso Específico | B10: Factor | C10: Resultado | D10: 1 | E10: 2 | F10: 3 | G10: 4 | H10: 5
A11: 0.2 | B11: Historial Buro de Crédito | C11: =+D12 -> 0.2 | D11: Sin cartera vencida ni mora en los ultimos dos años | E11: Sin cartera vencida ni mora en el último años | F11: Ha tenido un atraso máximo de 30 días en el último año | G11: Ha tenido un máximo de 2 atrasos de 30 días en el último año | H11: Ha tenido atrasos recurrentes y cartera vencida en el último año
D12: =$A$11*1 -> 0.2 | E12: =$A$11*0.75 -> 0.15 | F12: =$A$11*0.5 -> 0.1 | G12: =$A$11*0.25 -> 0.05 | H12: 0
A13: 0.1 | B13: Historial Buro de Crédito Socios | C13: =+D14 -> 0.1 | D13: Sin cartera vencida ni mora en los ultimos dos años | E13: Sin cartera vencida ni mora en el último años | F13: Ha tenido un atraso máximo de 30 días en el último año | G13: Ha tenido un máximo de dos atrasos de 30 días en el último año | H13: Ha tenido atrasos recurrentes y cartera vencida en el último año
D14: =$A$13*1 -> 0.1 | E14: =$A$13*0.75 -> 0.075 | F14: =$A$13*0.5 -> 0.05 | G14: =$A$13*0.25 -> 0.025 | H14: 0
B15: Historial con Moskalti | C15: =+H16 -> 0 | D15: Previa relacion crediticia, siempre al corriente en tiempo y forma | E15: Previa relacion crediticia, algun retraso menor, subsanado sin penalidad | F15: Previa relacion crediticia, algun retraso menor, subsanado con penalidad | G15: Previa relacion crediticia, varios retrasos subsanados con penalidad | H15: Previa relacion crediticia, mala experiencia con varios retrasos o morosidad
D16: =$A$15*1 -> 0 | E16: =$A$15*0.75 -> 0 | F16: =$A$15*0.5 -> 0 | G16: =$A$15*0.25 -> 0 | H16: 0
A17: 0.05 | B17: Calidad de la Informacion | C17: =+E18 -> 0.0375 | D17: La informacion es confiable, completa, oportuna, dictaminada por despacho independiente y demostrada en informacion fiscal | E17: La informacion es confiable, completa, oportuna, no dictaminada por despacho independiente pero demostrada en informacion fiscal | F17: La informacion es buena, confiable, suficiente y oportuna, no dictaminada pero materialmente demostrada en informacion fiscal | G17: La informacion es adecuada y confiable, con ciertos huecos no materiales | H17: La informacion es inadecuada
D18: =$A$17*1 -> 0.05 | E18: =$A$17*0.75 -> 0.0375 | F18: =$A$17*0.5 -> 0.025 | G18: =$A$17*0.25 -> 0.0125 | H18: 0
A19: 0.05 | B19: Calidad de Administración | C19: =+E20 -> 0.0375 | D19: Socios o administradores con mas de 5 años de experiencia en el sector y buena reputación | E19: Socios o administradores con mas de 3 años de experiencia en el sector y buena reputación | F19: Socios o administradores con experiencia relacionada y buena reputación | G19: Socios o administradores con buena experiencia profesional y buena reputación | H19: Socios o administradores sin experiencia material profesional o en el sector o dudosa reputación
D20: =$A$19*1 -> 0.05 | E20: =$A$19*0.75 -> 0.0375 | F20: =$A$19*0.5 -> 0.025 | G20: =$A$19*0.25 -> 0.0125 | H20: 0
B23: Solvencia y Viabilidad 30%
B24: Factor | C24: Peso | D24: 1 | E24: 2 | F24: 3 | G24: 4 | H24: 5
A25: 0.05 | B25: Activos Totales | C25: =+G26 -> 0.0125 | D25: >50 millones de pesos | E25: 10-50 millones de pesos | F25: 5-10 millones de pesos | G25: 3-5 millones de pesos | H25: < 3 millones de pesos
D26: =$A$25*1 -> 0.05 | E26: =$A$25*0.75 -> 0.0375 | F26: =$A$25*0.5 -> 0.025 | G26: =$A$25*0.25 -> 0.0125 | H26: 0 | J26: =+RF!E12 -> 0
A27: 0.05 | B27: Deuda Total / Activos Totales | C27: =+D28 -> 0.05 | D27: <25% | E27: 25-30% | F27: 30-40% | G27: 40-45% | H27: >45%
D28: =$A$27*1 -> 0.05 | E28: =$A$27*0.75 -> 0.0375 | F28: =$A$27*0.5 -> 0.025 | G28: =$A$27*0.25 -> 0.0125 | H28: 0 | J28: =+RF!E13 -> #DIV/0!
A29: 0.0335 | B29: Tendencia Apalancamiento vs Periodo Anterior | C29: =+D30 -> 0.0335 | D29: Menor en >20% | E29: Menor entre 10-20% | F29: Igual | G29: Mayor en 10-25% | H29: Mayor en >25%
D30: =$A$29*1 -> 0.0335 | E30: =$A$29*0.75 -> 0.025125 | F30: =$A$29*0.5 -> 0.01675 | G30: =$A$29*0.25 -> 0.008375 | H30: 0 | J30: =+RF!K14 -> #DIV/0!
A31: 0.0335 | B31: Activos Fijos / Activos Totales | C31: =+D32 -> 0.0335 | D31: >50% | E31: 40-50% | F31: 30-40% | G31: 20-30% | H31: <20%
D32: =$A$31*1 -> 0.0335 | E32: =$A$31*0.75 -> 0.025125 | F32: =$A$31*0.5 -> 0.01675 | G32: =$A$31*0.25 -> 0.008375 | H32: 0 | J32: =+RF!E15 -> #DIV/0!
A33: 0.0335 | B33: Riesgo del Sector | C33: =+F34 -> 0.01675 | D33: Sector de bajo riesgo, con baja morosidad | E33: Sector de menor riesgo, con menor morosidad | F33: Sector de riesgo moderado, con morosidad moderada | G33: Sector de mayor riesgo, con mayor morosidad | H33: Sector de alto riesgo, con alta morosidad
D34: =$A$33*1 -> 0.0335 | E34: =$A$33*0.75 -> 0.025125 | F34: =$A$33*0.5 -> 0.01675 | G34: =$A$33*0.25 -> 0.008375 | H34: 0
A35: 0.0335 | B35: Diversificación Financiera | C35: =+H36 -> 0 | D35: Amplio acceso a mercado de financiamiento | E35: Varias fuentes de financiamiento (>5) | F35: 4-5 fuentes de financiamiento | G35: 2 o 3 fuentes de financiamiento | H35: Unica fuente de financiamiento
D36: =$A$35*1 -> 0.0335 | E36: =$A$35*0.75 -> 0.025125 | F36: =$A$35*0.5 -> 0.01675 | G36: =$A$35*0.25 -> 0.008375 | H36: 0
A37: 0.0335 | B37: Diversificación Clientes | C37: =+H38 -> 0 | D37: Muy alta diversificacion de clientes (>25) | E37: Alta diversificacion de clientes (>15) | F37: Diversificacion moderada de clientes (10-15) | G37: Concentracion en clientes (5-10) | H37: Alta Concentracion en clientes (<5)
D38: =$A$37*1 -> 0.0335 | E38: =$A$37*0.75 -> 0.025125 | F38: =$A$37*0.5 -> 0.01675 | G38: =$A$37*0.25 -> 0.008375 | H38: 0
A39: 0.0335 | B39: Diversificación Provedores | C39: =+G40 -> 0.008375 | D39: Muy alta diversificacion de provedores (>25) | E39: Alta diversificacion de provedores (>15) | F39: Diversificacion moderada de provedores (10-15) | G39: Concentracion en provedores (5-10) | H39: Alta Concentracion en provedores (<5)
D40: =$A$39*1 -> 0.0335 | E40: =$A$39*0.75 -> 0.025125 | F40: =$A$39*0.5 -> 0.01675 | G40: =$A$39*0.25 -> 0.008375 | H40: 0
B43: Rentabilidad, Liquidez y Momentum 30%
B44: Factor | C44: Peso | D44: 1 | E44: 2 | F44: 3 | G44: 4 | H44: 5
A45: 0.075 | B45: Tiempo de Operación | C45: =+F46 -> 0.0375 | D45: Mas de 10 años de operación | E45: Entre 6 y 9 años de operación | F45: Entre 3 y 6 años de operación | G45: Menos de 3 años de operación | H45: Menos de 1 año de operación
...

Sheet Matriz de Credito y Tasas
A1: Matriz de Crédito y Garantías
C3: Garantía | J3: 1 | K3: 2 | L3: 3 | M3: 4 | N3: 5
C4: 1 | D4: 2 | E4: 3 | F4: 4 | G4: 5 | I4: A | J4: =C21 -> 17.2886 | K4: =D21 -> 19.2886 | L4: =E21 -> 23.2886 | M4: =F21 -> 29.2886 | N4: =G21 -> 37.2886
A5: Credito | B5: A | C5: A1 | D5: A2 | E5: A3 | F5: A4 | G5: A5 | I5: B | J5: =C22 -> 19.7886 | K5: =D22 -> 21.7886 | L5: =E22 -> 25.7886 | M5: =F22 -> 31.7886 | N5: =G22 -> 39.7886
B6: B | C6: B1 | D6: B2 | E6: B3 | F6: B4 | G6: B5 | I6: C | J6: =C23 -> 24.7886 | K6: =D23 -> 26.7886 | L6: =E23 -> 30.7886 | M6: =F23 -> 36.7886 | N6: =G23 -> 44.7886
B7: C | C7: C1 | D7: C2 | E7: C3 | F7: C4 | G7: C5 | I7: D | J7: =C24 -> 32.2886 | K7: =D24 -> 34.2886 | L7: =E24 -> 38.2886 | M7: =F24 -> 44.2886 | N7: =G24 -> 52.2886
B8: D | C8: D1 | D8: D2 | E8: D3 | F8: D4 | G8: D5 | I8: E | J8: =C25 -> 42.2886 | K8: =D25 -> 44.2886 | L8: =E25 -> 48.2886 | M8: =F25 -> 54.2886 | N8: =G25 -> 62.2886
B9: E | C9: E1 | D9: E2 | E9: E3 | F9: E4 | G9: E5
C11: Sobretasas Indicativas
B12: TIIE + | C12: 1 | D12: 2 | E12: 3 | F12: 4 | G12: 5
B13: A | C13: 1000 | D13: 1200 | E13: 1600 | F13: 2200 | G13: 3000
B14: B | C14: 1250 | D14: 1450 | E14: 1850 | F14: 2450 | G14: 3250
B15: C | C15: 1750 | D15: 1950 | E15: 2350 | F15: 2950 | G15: 3750
B16: D | C16: 2500 | D16: 2700 | E16: 3100 | F16: 3700 | G16: 4500
B17: E | C17: 3500 | D17: 3700 | E17: 4100 | F17: 4700 | G17: 5500
C19: Ejemplo Tasas Indicativas (% Anual) | Q19: Rango Tasas Indicativas (% Anual)
A20: TIIE | B20: =7.2886*100 -> 728.86 | C20: 1 | D20: 2 | E20: 3 | F20: 4 | G20: 5
B21: A | C21: =($B$20+C13)/100 -> 17.2886 | D21: =($B$20+D13)/100 -> 19.2886 | E21: =($B$20+E13)/100 -> 23.2886 | F21: =($B$20+F13)/100 -> 29.2886 | G21: =($B$20+G13)/100 -> 37.2886 | P21: =+B20 -> 728.86 | Q21: 1 | S21: 2 | U21: 3 | W21: 4 | Y21: 5
B22: B | C22: =($B$20+C14)/100 -> 19.7886 | D22: =($B$20+D14)/100 -> 21.7886 | E22: =($B$20+E14)/100 -> 25.7886 | F22: =($B$20+F14)/100 -> 31.7886 | G22: =($B$20+G14)/100 -> 39.7886 | Q22: Bajo | R22: Alto | S22: Bajo | T22: Alto | U22: Bajo | V22: Alto | W22: Bajo | X22: Alto | Y22: Bajo | Z22: Alto
B23: C | C23: =($B$20+C15)/100 -> 24.7886 | D23: =($B$20+D15)/100 -> 26.7886 | E23: =($B$20+E15)/100 -> 30.7886 | F23: =($B$20+F15)/100 -> 36.7886 | G23: =($B$20+G15)/100 -> 44.7886 | P23: A | Q23: =($B$20+C13)/100 -> 17.2886 | R23: =S23-0.01 -> 19.2786 | S23: =($B$20+D13)/100 -> 19.2886 | T23: =U23-0.01 -> 23.2786 | U23: =($B$20+E13)/100 -> 23.2886 | V23: =W23-0.01 -> 29.2786 | W23: =($B$20+F13)/100 -> 29.2886 | X23: =Y23-0.01 -> 37.2786 | Y23: =($B$20+G13)/100 -> 37.2886 | Z23: =Y24-0.01 -> 39.7786
B24: D | C24: =($B$20+C16)/100 -> 32.2886 | D24: =($B$20+D16)/100 -> 34.2886 | E24: =($B$20+E16)/100 -> 38.2886 | F24: =($B$20+F16)/100 -> 44.2886 | G24: =($B$20+G16)/100 -> 52.2886 | P24: B | Q24: =($B$20+C14)/100 -> 19.7886 | R24: =S24-0.01 -> 21.7786 | S24: =($B$20+D14)/100 -> 21.7886 | T24: =U24-0.01 -> 25.7786 | U24: =($B$20+E14)/100 -> 25.7886 | V24: =W24-0.01 -> 31.7786 | W24: =($B$20+F14)/100 -> 31.7886 | X24: =Y24-0.01 -> 39.7786 | Y24: =($B$20+G14)/100 -> 39.7886 | Z24: =Y25-0.01 -> 44.7786
B25: E | C25: =($B$20+C17)/100 -> 42.2886 | D25: =($B$20+D17)/100 -> 44.2886 | E25: =($B$20+E17)/100 -> 48.2886 | F25: =($B$20+F17)/100 -> 54.2886 | G25: =($B$20+G17)/100 -> 62.2886 | P25: C | Q25: =($B$20+C15)/100 -> 24.7886 | R25: =S25-0.01 -> 26.7786 | S25: =($B$20+D15)/100 -> 26.7886 | T25: =U25-0.01 -> 30.7786 | U25: =($B$20+E15)/100 -> 30.7886 | V25: =W25-0.01 -> 36.7786 | W25: =($B$20+F15)/100 -> 36.7886 | X25: =Y25-0.01 -> 44.7786 | Y25: =($B$20+G15)/100 -> 44.7886 | Z25: =Y26-0.01 -> 52.2786
P26: D | Q26: =($B$20+C16)/100 -> 32.2886 | R26: =S26-0.01 -> 34.2786 | S26: =($B$20+D16)/100 -> 34.2886 | T26: =U26-0.01 -> 38.2786 | U26: =($B$20+E16)/100 -> 38.2886 | V26: =W26-0.01 -> 44.2786 | W26: =($B$20+F16)/100 -> 44.2886 | X26: =Y26-0.01 -> 52.2786 | Y26: =($B$20+G16)/100 -> 52.2886 | Z26: =Y27-0.01 -> 62.2786
P27: E | Q27: =($B$20+C17)/100 -> 42.2886 | R27: =S27-0.01 -> 44.2786 | S27: =($B$20+D17)/100 -> 44.2886 | T27: =U27-0.01 -> 48.2786 | U27: =($B$20+E17)/100 -> 48.2886 | V27: =W27-0.01 -> 54.2786 | W27: =($B$20+F17)/100 -> 54.2886 | X27: =Y27-0.01 -> 62.2786 | Y27: =($B$20+G17)/100 -> 62.2886 | Z27: 66.57
A29: Calificacion de credito | C29: =+'Modelo de Crédito'!C73 -> 0.738375
A30: Calificacion Garantia | C30: 2
A31: Calificacion Final | C31: C 2
